Fatal Python error: Segmentation fault

Current thread 0x0000000113329000 (most recent call first):
  File "/Users/alexanderschiller/miniconda/envs/text/lib/python2.7/site-packages/pyglet/gl/base.py", line 358 in delete_texture
  File "/Users/alexanderschiller/miniconda/envs/text/lib/python2.7/site-packages/pyglet/image/__init__.py", line 1439 in __del__
  File "/Users/alexanderschiller/miniconda/envs/text/lib/python2.7/site-packages/pyglet/libs/darwin/cocoapy/runtime.py", line 922 in __new__
  File "/Users/alexanderschiller/miniconda/envs/text/lib/python2.7/site-packages/pyglet/libs/darwin/cocoapy/runtime.py", line 758 in __call__
  File "/Users/alexanderschiller/miniconda/envs/text/lib/python2.7/site-packages/pyglet/libs/darwin/cocoapy/runtime.py", line 785 in __call__
  File "/Users/alexanderschiller/miniconda/envs/text/lib/python2.7/site-packages/pyglet/app/cocoa.py", line 173 in notify
  File "/Users/alexanderschiller/miniconda/envs/text/lib/python2.7/site-packages/pyglet/app/base.py", line 59 in post_event
  File "/Users/alexanderschiller/miniconda/envs/text/lib/python2.7/site-packages/pyglet/media/__init__.py", line 380 in _sync_dispatch_to_player
  File "/Users/alexanderschiller/miniconda/envs/text/lib/python2.7/site-packages/pyglet/media/drivers/openal/__init__.py", line 433 in _update_play_cursor
  File "/Users/alexanderschiller/miniconda/envs/text/lib/python2.7/site-packages/pyglet/media/drivers/openal/__init__.py", line 437 in get_write_size
  File "/Users/alexanderschiller/miniconda/envs/text/lib/python2.7/site-packages/pyglet/media/drivers/openal/__init__.py", line 112 in run
  File "/Users/alexanderschiller/miniconda/envs/text/lib/python2.7/site-packages/pyglet/media/__init__.py", line 145 in _thread_run
  File "/Users/alexanderschiller/miniconda/envs/text/lib/python2.7/threading.py", line 763 in run
  File "/Users/alexanderschiller/miniconda/envs/text/lib/python2.7/threading.py", line 810 in __bootstrap_inner
  File "/Users/alexanderschiller/miniconda/envs/text/lib/python2.7/threading.py", line 783 in __bootstrap

Thread 0x00007fff7a4d3310 (most recent call first):
  File "/Users/alexanderschiller/miniconda/envs/text/lib/python2.7/site-packages/pyglet/graphics/vertexdomain.py", line 123 in create_attribute_usage
  File "/Users/alexanderschiller/miniconda/envs/text/lib/python2.7/site-packages/pyglet/graphics/vertexdomain.py", line 135 in create_domain
  File "/Users/alexanderschiller/miniconda/envs/text/lib/python2.7/site-packages/pyglet/graphics/__init__.py", line 451 in _get_domain
  File "/Users/alexanderschiller/miniconda/envs/text/lib/python2.7/site-packages/pyglet/graphics/__init__.py", line 371 in add
  File "/Users/alexanderschiller/miniconda/envs/text/lib/python2.7/site-packages/pyglet/sprite.py", line 390 in _create_vertex_list
  File "/Users/alexanderschiller/miniconda/envs/text/lib/python2.7/site-packages/pyglet/sprite.py", line 239 in __init__
  File "/Users/alexanderschiller/personal/acceptable_loss/effect.py", line 24 in __init__
  File "/Users/alexanderschiller/personal/acceptable_loss/effect.py", line 63 in bullet_wound
  File "/Users/alexanderschiller/personal/acceptable_loss/character.py", line 90 in on_hit
  File "/Users/alexanderschiller/personal/acceptable_loss/baseskills.py", line 114 in unpack
  File "/Users/alexanderschiller/personal/acceptable_loss/ability.py", line 111 in update
  File "/Users/alexanderschiller/personal/acceptable_loss/character.py", line 99 in update
  File "/Users/alexanderschiller/personal/acceptable_loss/utility.py", line 59 in update
  File "/Users/alexanderschiller/personal/acceptable_loss/states.py", line 317 in update
  File "main.py", line 73 in render
  File "main.py", line 125 in run
  File "main.py", line 135 in <module>
[1]    17312 segmentation fault  python main.py